Workbook

Sheet Talisman
E1: Rarity | F1: Skill 1 Group | G1: Skill 2 Group | H1: Skill 3 Group | I1: Possible Slot Combos
E2: RARE[5] | F2: 1 | G2: 6 | H2: 6 | I2: [1,1] [2,0] [2,1] [3,0]
E3: RARE[5] | F3: 1 | G3: 7 | H3: - | I3: [1,1] [2,0] [2,1] [3,0]
E4: RARE[5] | F4: 1 | G4: 8 | H4: 6 | I4: [1,1] [2,0] [2,1] [3,0]
E5: RARE[5] | F5: 1 | G5: 8 | H5: 8 | I5: [1,1] [2,0] [2,1] [3,0]
E6: RARE[5] | F6: 1 | G6: 9 | H6: - | I6: [1,1] [2,0] [2,1] [3,0]
E7: RARE[5] | F7: 1 | G7: 10 | H7: - | I7: [1,1] [2,0] [2,1] [3,0]
E8: RARE[6] | F8: 1 | G8: 1 | H8: 7 | I8: [1,0] [1,1] [2,0] [2,1]
E9: RARE[6] | F9: 1 | G9: 1 | H9: 10 | I9: [1,0] [1,1] [2,0] [2,1]
E10: RARE[6] | F10: 2 | G10: 6 | H10: 6 | I10: [1,0] [1,1] [2,0] [2,1]
E11: RARE[6] | F11: 2 | G11: 8 | H11: 6 | I11: [1,0] [1,1] [2,0] [2,1]
E12: RARE[6] | F12: 2 | G12: 8 | H12: 8 | I12: [1,0] [1,1] [2,0] [2,1]
E13: RARE[6] | F13: 2 | G13: 9 | H13: - | I13: [1,0] [1,1] [2,0] [2,1]
E14: RARE[6] | F14: 2 | G14: 10 | H14: - | I14: [1,0] [1,1] [2,0] [2,1]
E15: RARE[7] | F15: 2 | G15: 1 | H15: 7 | I15: [1,0] [1,1] [2,0]
E16: RARE[7] | F16: 2 | G16: 1 | H16: 8 | I16: [1,1] [2,0] [3,0]
E17: RARE[7] | F17: 2 | G17: 1 | H17: 10 | I17: [1,0] [1,1] [2,0]
E18: RARE[7] | F18: 3 | G18: 6 | H18: 5 | I18: [1,0] [1,1] [2,0]
E19: RARE[7] | F19: 3 | G19: 7 | H19: - | I19: [1,0] [1,1] [2,0]
E20: RARE[7] | F20: 3 | G20: 8 | H20: 5 | I20: [1,0] [1,1] [2,0]
E21: RARE[7] | F21: 3 | G21: 10 | H21: - | I21: [1,0] [1,1] [2,0]
E22: RARE[7] | F22: 4 | G22: 1 | H22: 1 | I22: [1,0] [1,1] [2,0]
E23: RARE[8] | F23: 2 | G23: 1 | H23: 7 | I23: [W1,0] [W1,1] [W1,1,1]
E24: RARE[8] | F24: 2 | G24: 1 | H24: 8 | I24: [W1,0] [W1,1] [W1,1,1]
E25: RARE[8] | F25: 2 | G25: 1 | H25: 10 | I25: [W1,0] [W1,1] [W1,1,1]
E26: RARE[8] | F26: 3 | G26: 6 | H26: 5 | I26: [W1,0] [W1,1] [W1,1,1]
E27: RARE[8] | F27: 3 | G27: 7 | H27: - | I27: [W1,0] [W1,1] [W1,1,1]
E28: RARE[8] | F28: 3 | G28: 8 | H28: 5 | I28: [W1,0] [W1,1] [W1,1,1]
E29: RARE[8] | F29: 3 | G29: 10 | H29: - | I29: [W1,0] [W1,1] [W1,1,1]
E30: RARE[8] | F30: 4 | G30: 1 | H30: 1 | I30: [W1,0] [W1,1] [W1,1,1]

Sheet SkillGroups
A1: Group 1 | D1: Group 2 | G1: Group 3 | J1: Group 4 | M1: Group 5 | P1: Group 6 | S1: Group 7 | V1: Group 8 | Y1: Group 9 | AB1: Group 10
A2: Artillery | B2: 1 | D2: Airborne | E2: 1 | G2: Artillery | H2: 3 | J2: Attack Boost | K2: 2 | M2: Adaptability | N2: 1 | P2: Adaptability | Q2: 2 | S2: Antivirus | T2: 3 | V2: Ambush | W2: 1 | Y2: Ambush | Z2: 2 | AB2: Adrenaline Rush | AC2: 1
A3: Attack Boost | B3: 1 | D3: Artillery | E3: 2 | G3: Attack Boost | H3: 3 | J3: Ballistics | K3: 2 | M3: Antivirus | N3: 1 | P3: Antivirus | Q3: 2 | S3: Bind Resistance | T3: 3 | V3: Blight Resistance | W3: 1 | Y3: Blight Resistance | Z3: 2 | AB3: Agitator | AC3: 1
A4: Ballistics | B4: 1 | D4: Attack Boost | E4: 2 | G4: Ballistics | H4: 3 | J4: Blast Attack | K4: 2 | M4: Aquatic/Oilsilt Mobility | N4: 1 | P4: Aquatic/Oilsilt Mobility | Q4: 2 | S4: Blast Resistance | T4: 3 | V4: Coalescence | W4: 1 | Y4: Coalescence | Z4: 2 | AB4: Burst | AC4: 1
A5: Blast Attack | B5: 1 | D5: Ballistics | E5: 2 | G5: Blast Attack | H5: 3 | J5: Critical Boost | K5: 1 | M5: Bind Resistance | N5: 1 | P5: Bind Resistance | Q5: 2 | S5: Bleeding Resistance | T5: 3 | V5: Counterstrike | W5: 1 | Y5: Counterstrike | Z5: 2 | AB5: Convert Element | AC5: 1
A6: Bludgeoner | B6: 1 | D6: Blast Attack | E6: 2 | G6: Bludgeoner | H6: 3 | J6: Critical Element | K6: 2 | M6: Blast Resistance | N6: 1 | P6: Blast Resistance | Q6: 2 | S6: Bombardier | T6: 3 | V6: Earplugs | W6: 1 | Y6: Earplugs | Z6: 2 | AB6: Elemental Absorption | AC6: 1
A7: Charge Master | B7: 1 | D7: Blast Functionality | E7: 1 | G7: Charge Master | H7: 3 | J7: Critical Eye | K7: 2 | M7: Bleeding Resistance | N7: 1 | P7: Bleeding Resistance | Q7: 2 | S7: Botanist | T7: 4 | V7: Evade Extender | W7: 1 | Y7: Evade Extender | Z7: 2 | AB7: Flayer | AC7: 1
A8: Critical Draw | B8: 1 | D8: Bludgeoner | E8: 2 | G8: Critical Draw | H8: 3 | J8: Dragon Attack | K8: 2 | M8: Bombardier | N8: 1 | P8: Bombardier | Q8: 2 | S8: Constitution | T8: 4 | V8: Evade Window | W8: 2 | Y8: Evade Window | Z8: 3 | AB8: Foray | AC8: 1
A9: Critical Element | B9: 1 | D9: Charge Master | E9: 2 | G9: Critical Element | H9: 3 | J9: Fire Attack | K9: 2 | M9: Botanist | N9: 2 | P9: Botanist | Q9: 3 | S9: Defense Boost | T9: 4 | V9: Heroics | W9: 2 | Y9: Heroics | Z9: 3 | AB9: Latent Power | AC9: 1
A10: Critical Eye | B10: 1 | D10: Charge Up | E10: 1 | G10: Critical Eye | H10: 3 | J10: Guard | K10: 2 | M10: Constitution | N10: 2 | P10: Constitution | Q10: 3 | S10: Divine Blessing | T10: 3 | V10: Maximum Might | W10: 1 | Y10: Maximum Might | Z10: 2 | AB10: Weakness Exploit | AC10: 1
A11: Critical Status | B11: 1 | D11: Critical Draw | E11: 2 | G11: Critical Status | H11: 3 | J11: Guard Up | K11: 2 | M11: Defense Boost | N11: 2 | P11: Defense Boost | Q11: 3 | S11: Dragon Resistance | T11: 3 | V11: Mushroomancer | W11: 1 | Y11: Mushroomancer | Z11: 2
A12: Dragon Attack | B12: 1 | D12: Critical Element | E12: 2 | G12: Dragon Attack | H12: 3 | J12: Handicraft | K12: 2 | M12: Divine Blessing | N12: 1 | P12: Divine Blessing | Q12: 2 | S12: Fire Resistance | T12: 3 | V12: Partbreaker | W12: 1 | Y12: Partbreaker | Z12: 2
A13: Fire Attack | B13: 1 | D13: Critical Eye | E13: 2 | G13: Fire Attack | H13: 3 | J13: Ice Attack | K13: 2 | M13: Dragon Resistance | N13: 1 | P13: Dragon Resistance | Q13: 2 | S13: Flinch Free | T13: 3 | V13: Peak Performance | W13: 1 | Y13: Peak Performance | Z13: 2
A14: Focus | B14: 1 | D14: Critical Status | E14: 2 | G14: Focus | H14: 3 | J14: Opening Shot | K14: 2 | M14: Fire Resistance | N14: 1 | P14: Fire Resistance | Q14: 2 | S14: Free Meal | T14: 3 | V14: Resentment | W14: 1 | Y14: Resentment | Z14: 2
A15: Guard | B15: 1 | D15: Dragon Attack | E15: 2 | G15: Guard | H15: 3 | J15: Paralysis Attack | K15: 2 | M15: Flinch Free | N15: 1 | P15: Flinch Free | Q15: 2 | S15: Geologist | T15: 3 | V15: Stamina Surge | W15: 1 | Y15: Stamina Surge | Z15: 2
A16: Guard Up | B16: 1 | D16: Exhaust Functionality | E16: 1 | G16: Guard Up | H16: 3 | J16: Poison Attack | K16: 2 | M16: Free Meal | N16: 1 | P16: Free Meal | Q16: 2 | S16: Hunger Resistance | T16: 3 | V16: Tool Specialist | W16: 2 | Y16: Tool Specialist | Z16: 3
A17: Handicraft | B17: 1 | D17: Fire Attack | E17: 2 | G17: Handicraft | H17: 3 | J17: Protective Polish | K17: 2 | M17: Geologist | N17: 1 | P17: Geologist | Q17: 2 | S17: Ice Resistance | T17: 3
A18: Horn Maestro | B18: 1 | D18: Focus | E18: 2 | G18: Ice Attack | H18: 3 | J18: Razor Sharp | K18: 2 | M18: Hunger Resistance | N18: 1 | P18: Hunger Resistance | Q18: 2 | S18: Intimidator | T18: 3
A19: Ice Attack | B19: 1 | D19: Guard | E19: 2 | G19: Master's Touch | H19: 1 | J19: Sleep Attack | K19: 2 | M19: Ice Resistance | N19: 1 | P19: Ice Resistance | Q19: 2 | S19: Iron Skin | T19: 3
A20: Load Shells | B20: 1 | D20: Guard Up | E20: 2 | G20: Mind's Eye | H20: 3 | J20: Tetrad Shot | K20: 2 | M20: Intimidator | N20: 1 | P20: Intimidator | Q20: 2 | S20: Item Prolonger | T20: 3
A21: Mind's Eye | B21: 1 | D21: Handicraft | E21: 2 | G21: Normal Shots | H21: 1 | J21: Thunder Attack | K21: 2 | M21: Iron Skin | N21: 1 | P21: Iron Skin | Q21: 2 | S21: Marathon Runner | T21: 3
A22: Offensive Guard | B22: 1 | D22: Horn Maestro | E22: 2 | G22: Offensive Guard | H22: 3 | J22: Water Attack | K22: 2 | M22: Item Prolonger | N22: 1 | P22: Item Prolonger | Q22: 2 | S22: Paralysis Resistance | T22: 3
A23: Opening Shot | B23: 1 | D23: Ice Attack | E23: 2 | G23: Opening Shot | H23: 3 | M23: Marathon Runner | N23: 1 | P23: Marathon Runner | Q23: 2 | S23: Poison Resistance | T23: 3
A24: Paralysis Attack | B24: 1 | D24: Load Shells | E24: 2 | G24: Para Functionality | H24: 1 | M24: Paralysis Resistance | N24: 1 | P24: Paralysis Resistance | Q24: 2 | S24: Quick Sheathe | T24: 3
A25: Poison Attack | B25: 1 | D25: Mind's Eye | E25: 2 | G25: Paralysis Attack | H25: 3 | M25: Poison Resistance | N25: 1 | P25: Poison Resistance | Q25: 2 | S25: Recovery Speed | T25: 3
A26: Power Prolonger | B26: 1 | D26: Offensive Guard | E26: 2 | G26: Piercing Shots | H26: 1 | M26: Quick Sheathe | N26: 1 | P26: Quick Sheathe | Q26: 2 | S26: Recovery Up | T26: 3
A27: Protective Polish | B27: 1 | D27: Opening Shot | E27: 2 | G27: Poison Attack | H27: 3 | M27: Recovery Speed | N27: 1 | P27: Recovery Speed | Q27: 2 | S27: Sleep Resistance | T27: 3
A28: Punishing Draw | B28: 1 | D28: Paralysis Attack | E28: 2 | G28: Power Prolonger | H28: 3 | M28: Recovery Up | N28: 1 | P28: Recovery Up | Q28: 2 | S28: Speed Eating | T28: 3
A29: Rapid Morph | B29: 1 | D29: Poison Attack | E29: 2 | G29: Protective Polish | H29: 3 | M29: Sleep Resistance | N29: 1 | P29: Sleep Resistance | Q29: 2 | S29: Stun Resistance | T29: 3
A30: Razor Sharp | B30: 1 | D30: Poison Duration Up | E30: 1 | G30: Punishing Draw | H30: 3 | M30: Speed Eating | N30: 1 | P30: Speed Eating | Q30: 2 | S30: Survival Expert | T30: 3
A31: Sleep Attack | B31: 1 | D31: Poison Functionality | E31: 1 | G31: Rapid Fire Up | H31: 1 | M31: Stench Resistance | N31: 1 | P31: Stench Resistance | Q31: 2 | S31: Thunder Resistance | T31: 3
A32: Slugger | B32: 1 | D32: Power Prolonger | E32: 2 | G32: Rapid Morph | H32: 3 | M32: Stun Resistance | N32: 1 | P32: Stun Resistance | Q32: 2 | S32: Tremor Resistance | T32: 3
A33: Special Ammo Boost | B33: 1 | D33: Protective Polish | E33: 2 | G33: Razor Sharp | H33: 3 | M33: Survival Expert | N33: 1 | P33: Survival Expert | Q33: 2 | S33: Water Resistance | T33: 3
A34: Speed Sharpening | B34: 1 | D34: Punishing Draw | E34: 2 | G34: Sleep Attack | H34: 3 | M34: Thunder Resistance | N34: 1 | P34: Thunder Resistance | Q34: 2 | S34: Wide-Range | T34: 4
A35: Stamina Thief | B35: 1 | D35: Rapid Morph | E35: 2 | G35: Sleep Functionality | H35: 1 | M35: Tremor Resistance | N35: 1 | P35: Tremor Resistance | Q35: 2 | S35: Windproof | T35: 3
A36: Tetrad Shot | B36: 1 | D36: Razor Sharp | E36: 2 | G36: Slugger | H36: 3 | M36: Water Resistance | N36: 1 | P36: Water Resistance | Q36: 2
A37: Thunder Attack | B37: 1 | D37: Sleep Attack | E37: 2 | G37: Spread/Power Shots | H37: 1 | M37: Wide-Range | N37: 2 | P37: Wide-Range | Q37: 3
A38: Water Attack | B38: 1 | D38: Slugger | E38: 2 | G38: Stamina Thief | H38: 3 | M38: Windproof | N38: 1 | P38: Windproof | Q38: 2
D39: Special Ammo Boost | E39: 2 | G39: Tetrad Shot | H39: 3
D40: Speed Sharpening | E40: 2 | G40: Thunder Attack | H40: 3
...

Sheet PossibleLayouts
A1: Rarity | B1: Skill 1 Group | C1: Skill 2 Group | D1: Skill 3 Group | E1: Possible Slot Combos
A2: RARE[5] | B2: 1 | C2: 6 | D2: 6 | E2: [1,1] [2,0] [2,1] [3,0] | G2: [1,0] | H2: 1-0-0
A3: RARE[5] | B3: 1 | C3: 7 | D3: - | E3: [1,1] [2,0] [2,1] [3,0] | G3: [1,1] | H3: 1-1-0
A4: RARE[5] | B4: 1 | C4: 8 | D4: 6 | E4: [1,1] [2,0] [2,1] [3,0] | G4: [2,0] | H4: 2-0-0
A5: RARE[5] | B5: 1 | C5: 8 | D5: 8 | E5: [1,1] [2,0] [2,1] [3,0] | G5: [2,1] | H5: 2-1-0
A6: RARE[5] | B6: 1 | C6: 9 | D6: - | E6: [1,1] [2,0] [2,1] [3,0] | G6: [3,0] | H6: 3-0-0
A7: RARE[5] | B7: 1 | C7: 10 | D7: - | E7: [1,1] [2,0] [2,1] [3,0] | G7: [W1,0] | H7: 1w-0-0
A8: RARE[6] | B8: 1 | C8: 1 | D8: 7 | E8: [1,0] [1,1] [2,0] [2,1] | G8: [W1,1] | H8: 1w-1-0
A9: RARE[6] | B9: 1 | C9: 1 | D9: 10 | E9: [1,0] [1,1] [2,0] [2,1] | G9: [W1,1,1] | H9: 1w-1-1
A10: RARE[6] | B10: 2 | C10: 6 | D10: 6 | E10: [1,0] [1,1] [2,0] [2,1]
A11: RARE[6] | B11: 2 | C11: 8 | D11: 6 | E11: [1,0] [1,1] [2,0] [2,1]
A12: RARE[6] | B12: 2 | C12: 8 | D12: 8 | E12: [1,0] [1,1] [2,0] [2,1]
A13: RARE[6] | B13: 2 | C13: 9 | D13: - | E13: [1,0] [1,1] [2,0] [2,1]
A14: RARE[6] | B14: 2 | C14: 10 | D14: - | E14: [1,0] [1,1] [2,0] [2,1]
A15: RARE[7] | B15: 2 | C15: 1 | D15: 7 | E15: [1,0] [1,1] [2,0]
A16: RARE[7] | B16: 2 | C16: 1 | D16: 8 | E16: [1,1] [2,0] [3,0]
A17: RARE[7] | B17: 2 | C17: 1 | D17: 10 | E17: [1,0] [1,1] [2,0]
A18: RARE[7] | B18: 3 | C18: 6 | D18: 5 | E18: [1,0] [1,1] [2,0]
A19: RARE[7] | B19: 3 | C19: 7 | D19: - | E19: [1,0] [1,1] [2,0]
A20: RARE[7] | B20: 3 | C20: 8 | D20: 5 | E20: [1,0] [1,1] [2,0]
A21: RARE[7] | B21: 3 | C21: 10 | D21: - | E21: [1,0] [1,1] [2,0]
A22: RARE[7] | B22: 4 | C22: 1 | D22: 1 | E22: [1,0] [1,1] [2,0]
A23: RARE[8] | B23: 2 | C23: 1 | D23: 7 | E23: [W1,0] [W1,1] [W1,1,1]
A24: RARE[8] | B24: 2 | C24: 1 | D24: 8 | E24: [W1,0] [W1,1] [W1,1,1]
A25: RARE[8] | B25: 2 | C25: 1 | D25: 10 | E25: [W1,0] [W1,1] [W1,1,1]
A26: RARE[8] | B26: 3 | C26: 6 | D26: 5 | E26: [W1,0] [W1,1] [W1,1,1]
A27: RARE[8] | B27: 3 | C27: 7 | D27: - | E27: [W1,0] [W1,1] [W1,1,1]
A28: RARE[8] | B28: 3 | C28: 8 | D28: 5 | E28: [W1,0] [W1,1] [W1,1,1]
A29: RARE[8] | B29: 3 | C29: 10 | D29: - | E29: [W1,0] [W1,1] [W1,1,1]
A30: RARE[8] | B30: 4 | C30: 1 | D30: 1 | E30: [W1,0] [W1,1] [W1,1,1]
B32: =unique(B2:B30) -> 1 | C32: =unique(C2:C30) -> 6 | D32: =unique(D2:D30) -> 6
B33: 2 | C33: 7 | D33: -
B34: 3 | C34: 8 | D34: 8
B35: 4 | C35: 9 | D35: 7
C36: 10 | D36: 10
C37: 1 | D37: 5
D38: 1

Sheet Backdoors
A1: only 1,2,3,4 | D1: Possible 2nd Groups | K1: Possible 2s | P1: Possible 3rd Groups | W1: Possible 3s | AD1: slots
D2: =IFERROR(__xludf.DUMMYFUNCTION("filter($A$4:$A$13,$B$4:$B$13=#REF!)"),"#N/A") -> #N/A | F2: =IFERROR(__xludf.DUMMYFUNCTION("ifna(join("","",unique(filter(PossibleLayouts!$C$2:$C$30,PossibleLayouts!$B$2:$B$30=$D$2))),"""")"),"") | P2: =IFERROR(__xludf.DUMMYFUNCTION("filter($M$14:$M$23,$N$14:$N$23=#REF!)"),"#N/A") -> #N/A | R2: =IFERROR(__xludf.DUMMYFUNCTION("ifna(join("","",unique(filter(PossibleLayouts!$D$2:$D$30,PossibleLayouts!$C$2:$C$30=$P$2,PossibleLayouts!$B$2:$B$30=$D$2))),"""")"),"") | AB2: =IFERROR(__xludf.DUMMYFUNCTION("if($W$3=""None"",""-"",filter($Y$14:$Y$23,$Z$14:$Z$23=#REF!))"),"-") -> - | AD2: combination
A3: Group | F3: =IFERROR(__xludf.DUMMYFUNCTION("ifna(join("","",unique(filter(PossibleLayouts!$C$2:$C$30,PossibleLayouts!$B$2:$B$30=$D$3))),"""")"),"") | G3: =if(and($D$3=4,$AD$5=1),$D$3,$D$2) -> #N/A | K3: =IFERROR(__xludf.DUMMYFUNCTION("transpose(unique(split(join("","",D$7:D1000,E$7:E1000,F$7:F1000,G$7:G1000,H$7:H1000,I$7:I1000),"",""),1))"),",,,,,,,,,,,,,,,,,,,,,,,,,,,,,,,,,,,,,,,,,,,,,,,,,,,,,,,,,,,,,,,,,,,,,,,,,,,,,,,,,,,,,,,,,,,,,,,,,,,,,,,,,,,,,,,,,,,,,,,,,,,,,,,,,,,,,,,,,,,,,,,,,,,,,,,,,,,,,,,,,,,,,,,,,,,,,,,,,,,,,,,,,,,,,,,,,,,,,,,,,,,,,,,,,,,,,,,,,,,,,,,,,,,,,,,,,,,,,,,,,,,,,,,,,,,,,,,"&",,,,,,,,,,,,,,,,,,,,,,,,,,,,,,,,,,,,,,,,,,,,,,,,,,,,,,,,,,,,,,,,,,,,,,,,,,,,,,,,,,,,,,,,,,,,,,,,,,,,,,,,,,,,,,,,,,,,,,,,,,,,,,,,,,,,,,,,,,,,,,,,,,,,,,,,,,,,,,,,,,,,,,,,,,,,,,,,,,,,,,,,,,,,,,,,,,,,,,,,,,,,,,,,,,,,,,,,,,,,,,,,,,,,,,,,,,,,,,,,,,,,,,,,,,,,,,,"&",,,,,,,,,,,,,,,,,,,,,,,,,,,,,,,,,,,,,,,,,,,,,,,,,,,,,,,,,,,,,,,,,,,,,,,,,,,,,,,,,,,,,,,,,,,,,,,,,,,,,,,,,,,,,,,,,,,,,,,,,,,,,,,,,,,,,,,,,,,,,,,,,,,,,,,,,,,,,,,,,,,,,,,,,,,,,,,,,,,,,,,,,,,,,,,,,,,,,,,,,,,,,,,,,,,,,,,,,,,,,,,,,,,,,,,,,,,,,,,,,,,,,,,,,,,,,,,"&",,,,,,,,,,,,,,,,,,,,,,,,,,,,,,,,,,,,,,,,,,,,,,,,,,,,,,,,,,,,,,,,,,,,,,,,,,,,,,,,,,,,,,,,,,,,,,,,,,,,,,,,,,,,,,,,,,,,,,,,,,,,,,,,,,,,,,,,,,,,,,,,,,,,,,,,,,,,,,,,,,,,,,,,,,,,,,,,,,,,,,,,,,,,,,,,,,,,,,,,,,,,,,,,,,,,,,,,,,,,,,,,,,,,,,,,,,,,,,,,,,,,,,,,,,,,,,,"&",,,,,,,,,,,,,,,,,,,,,,,,,,,,,,,,,,,,,,,,,,,,,,,,,,,,,,,,,,,,,,,,,,,,,,,,,,,,,,,,,,,,,,,,,,,,,,,,,,,,,,,,,,,,,,,,,,,,,,,,,,,,,,,,,,,,,,,,,,,,,,,,,,,,,,,,,,,,,,,,,,,,,,,,,,,,,,,,,,,,,,,,,,,,,,,,,,,,,,,,,,,,,,,,,,,,,,,,,,,,,,,,,,,,,,,,,,,,,,,,,,,,,,,,,,,,,,,"&",,,,,,,,,,,,,,,,,,,,,,,,,,,,,,,,,,,,,,,,,,,,,,,,,,,,,,,,,,,,,,,,,,,,,,,,,,,,,,,,,,,,,,,,,,,,,,,,,,,,,,,,,,,,,,,,,,,,,,,,,,,,,,,,,,,,,,,,,,,,,,,,,,,,,,,,,,,,,,,,,,,,,,,,,,,,,,,,,,,,,,,,,,,,,,,,,,,,,,,,,,,,,,,,,,,,,,,,,,,,,,,,,,,,,,,,,,,,,,,,,,,,,,,,,,,,,,,"&",,,,,,,,,,,,,,,,,,,,,,,,,,,,,,,,,,,,,,,,,,,,,,,,,,,,,,,,,,,,,,,,,,,,,,,,,,,,,,,,,,,,,,,,,,,,,,,,,,,,,,,,,,,,,,,,,,,,,,,,,,,,,,,,,,,,,,,,,,,,,,,,,,,,,,,,,,,,,,,,,,,,,,,,,,,,,,,,,,,,,,,,,,,,,,,,,,,,,,,,,,,,,,,,,,,,,,,,,,,,,,,,,,,,,,,,,,,,,,,,,,,,,,,,,,,,,,,"&",,,,,,,,,,,,,,,,,,,,,,,,,,,,,,,,,,,,,,,,,,,,,,,,,,,,,,,,,,,,,,,,,,,,,,,,,,,,,,,,,,,,,,,,,,,,,,,,,,,,,,,,,,,,,,,,,,,,,,,,,,,,,,,,,,,,,,,,,,,,,,,,,,,,,,,,,,,,,,,,,,,,,,,,,,,,,,,,,,,,,,,,,,,,,,,,,,,,,,,,,,,,,,,,,,,,,,,,,,,,,,,,,,,,,,,,,,,,,,,,,,,,,,,,,,,,,,,"&",,,,,,,,,,,,,,,,,,,,,,,,,,,,,,,,,,,,,,,,,,,,,,,,,,,,,,,,,,,,,,,,,,,,,,,,,,,,,,,,,,,,,,,,,,,,,,,,,,,,,,,,,,,,,,,,,,,,,,,,,,,,,,,,,,,,,,,,,,,,,,,,,,,,,,,,,,,,,,,,,,,,,,,,,,,,,,,,,,,,,,,,,,,,,,,,,,,,,,,,,,,,,,,,,,,,,,,,,,,,,,,,,,,,,,,,,,,,,,,,,,,,,,,,,,,,,,,"&",,,,,,,,,,,,,,,,,,,,,,,,,,,,,,,,,,,,,,,,,,,,,,,,,,,,,,,,,,,,,,,,,,,,,,,,,,,,,,,,,,,,,,,,,,,,,,,,,,,,,,,,,,,,,,,,,,,,,,,,,,,,,,,,,,,,,,,,,,,,,,,,,,,,,,,,,,,,,,,,,,,,,,,,,,,,,,,,,,,,,,,,,,,,,,,,,,,,,,,,,,,,,,,,,,,,,,,,,,,,,,,,,,,,,,,,,,,,,,,,,,,,,,,,,,,,,,,"&",,,,,,,,,,,,,,,,,,,,,,,,,,,,,,,,,,,,,,,,,,,,,,,,,,,,,,,,,,,,,,,,,,,,,,,,,,,,,,,,,,,,,,,,,,,,,,,,,,,,,,,,,,,,,,,,,,,,,,,,,,,,,,,,,,,,,,,,,,,,,,,,,,,,,,,,,,,,,,,,,,,,,,,,,,,,,,,,,,,,,,,,,,,,,,,,,,,,,,,,,,,,,,,,,,,,,,,,,,,,,,,,,,,,,,,,,,,,,,,,,,,,,,,,,,,,,,,"&",,,,,,,,,,,,,,,,,,,,,,,,,,,,,,,,,,,,,,,,,,,,,,,,,,,,,,,,,,,,,,,,,,,,,,,,,,,,,,,,,,,,,,,,,,,,,,,,,,,,,,,,,,,,,,,,,,,,,,,,,,,,,,,,,,,,,,,,,,,,,,,,,,,,,,,,,,,,,,,,,,,,,,,,,,,,,,,,,,,,,,,,,,,,,,,,,,,,,,,,,,,,,,,,,,,,,,,,,,,,,,,,,,,,,,,,,,,,,,,,,,,,,,,,,,,,,,,"&",,,,,,,,,,,,,,,,,,,,,,,,,,,,,,,,,,,,,,,,,,,,,,,,,,,,,,,,,,,,,,,,,,,,,,,,,,,,,,,,,,,,,,,,,,,,,,,,,,,,,,,,,,,,,,,,,,,,,,,,,,,,,,,,,,,,,,,,,,,,,,,,,,,,,,,,,,,,,,,,,,,,,,,,,,,,,,,,,,,,,,,,,,,,,,,,,,,,,,,,,,,,,,,,,,,,,,,,,,,,,,,,,,,,,,,,,,,,,,,,,,,,,,,,,,,,,,,"&",,,,,,,,,,,,,,,,,,,,,,,,,,,,,,,,,,,,,,,,,,,,,,,,,,,,,,,,,,,,,,,,,,,,,,,,,,,,,,,,,,,,,,,,,,,,,,,,,,,,,,,,,,,,,,,,,,,,,,,,,,,,,,,,,,,,,,,,,,,,,,,,,,,,,,,,,,,,,,,,,,,,,,,,,,,,,,,,,,,,,,,,,,,,,,,,,,,,,,,,,,,,,,,,,,,,,,,,,,,,,,,,,,,,,,,,,,,,,,,,,,,,,,,,,,,,,,,"&",,,,,,,,,,,,,,,,,,,,,,,,,,,,,,,,,,,,,,,,,,,,,,,,,,,,,,,,,,,,,,,,,,,,,,,,,,,,,,,,,,,,,,,,,,,,,,,,,,,,,,,,,,,,,,,,,,,,,,,,,,,,,,,,,,,,,,,,,,,,,,,,,,,,,,,,,,,,,,,,,,,,,,,,,,,,,,,,,,,,,,,,,,,,,,,,,,,,,,,,,,,,,,,,,,,,,,,,,,,,,,,,,,,,,,,,,,,,,,,,,,,,,,,,,,,,,,,"&",,,,,,,,,,,,,,,,,,,,,,,,,,,,,,,,,,,,,,,,,,,,,,,,,,,,,,,,,,,,,,,,,,,,,,,,,,,,,,,,,,,,,,,,,,,,,,,,,,,,,,,,,,,,,,,,,,,,,,,,,,,,,,,,,,,,,,,,,,,,,,,,,,,,,,,,,,,,,,,,,,,,,,,,,,,,,,,,,,,,,,,,,,,,,,,,,,,,,,,,,,,,,,,,,,,,,,,,,,,,,,,,,,,,,,,,,,,,,,,,,,,,,,,,,,,,,,,"&",,,,,,,,,,,,,,,,,,,,,,,,,,,,,,,,,,,,,,,,,,,,,,,,,,,,,,,,,,,,,,,,,,,,,,,,,,,,,,,,,,,,,,,,,,,,,,,,,,,,,,,,,,,,,,,,,,,,,,,,,,,,,,,,,,,,,,,,,,,,,,,,,,,,,,,,,,,,,,,,,,,,,,,,,,,,,,,,,,,,,,,,,,,,,,,,,,,,,,,,,,,,,,,,,,,,,,,,,,,,,,,,,,,,,,,,,,,,,,,,,,,,,,,,,,,,,,,"&",,,,,,,,,,,,,,,,,,,,,,,,,,,,,,,,,,,,,,,,,,,,,,,,,,,,,,,,,,,,,,,,,,,,,,,,,,,,,,,,,,,,,,,,,,,,,,,,,,,,,,,,,,,,,,,,,,,,,,,,,,,,,,,,,,,,,,,,,,,,,,,,,,,,,,,,,,,,,,,,,,,,,,,,,,,,,,,,,,,,,,,,,,,,,,,,,,,,,,,,,,,,,,,,,,,,,,,,,,,,,,,,,,,,,,,,,,,,,,,,,,,,,,,,,,,,,,,"&",,,,,,,,,,,,,,,,,,,,,,,,,,,,,,,,,,,,,,,,,,,,,,,,,,,,,,,,,,,,,,,,,,,,,,,,,,,,,,,,,,,,,,,,,,,,,,,,,,,,,,,,,,,,,,,,,,,,,,,,,,,,,,,,,,,,,,,,,,,,,,,,,,,,,,,,,,,,,,,,,,,,,,,,,,,,,,,,,,,,,,,,,,,,,,,,,,,,,,,,,,,,,,,,,,,,,,,,,,,,,,,,,,,,,,,,,,,,,,,,,,,,,,,,,,,,,,,"&",,,,,,,,,,,,,,,,,,,,,,,,,,,,,,,,,,,,,,,,,,,,,,,,,,,,,,,,,,,,,,,,,,,,,,,,,,,,,,,,,,,,,,,,,,,,,,,,,,,,,,,,,,,,,,,,,,,,,,,,,,,,,,,,,,,,,,,,,,,,,,,,,,,,,,,,,,,,,,,,,,,,,,,,,,,,,,,,,,,,,,,,,,,,,,,,,,,,,,,,,,,,,,,,,,,,,,,,,,,,,,,,,,,,,,,,,,,,,,,,,,,,,,,,,,,,,,,"&",,,,,,,,,,,,,,,,,,,,,,,,,,,,,,,,,,,,,,,,,,,,,,,,,,,,,,,,,,,,,,,,,,,,,,,,,,,,,,,,,,,,,,,,,,,,,,,,,,,,,,,,,,,,,,,,,,,,,,,,,,,,,,,,,,,,,,,,,,,,,,,,,,,,,,,,,,,,,,,,,,,,,,,,,,,,,,,,,,,,,,,,,,,,,,,,,,,,,,,,,,,,,,,,,,,,,,,,,,,,,,,,,,,,,,,,,,,,,,,,,,,,,,,,,,,,,,,"&",,,,,,,,,,,,,,,,,,,,,,,,,,,,,,,,,,,,,,,,,,,,,,,,,,,,,,,,,,,,,,,,,,,,,,,,,,,,,,,,,,,,,,,,,,,,,,,,,,,,,,,,,,,,,,,,,,,,,,,,,,,,,,,,,,,,,,,,,,,,,,,,,,,,,,,,,,,,,,,,,,,,,,,,,,,,,,,,,,,,,,,,,,,,,,,,,,,,,,,,,,,,,,,,,,,,,,,,,,,,,,,,,,,,,,,,,,,,,,,,,,,,,,,,,,,,,,,"&",,,,,,,,,,,,,,,,,,,,,,,,,,,,,,,,,,,,,,,,,,,,,,,,,,,,,,,,,,,,,,,,,,,,,,,,,,,,,,,,,,,,,,,,,,,,,,,,,,,,,,,,,,,,,,,,,,,,,,,,,,,,,,,,,,,,,,,,,,,,,,,,,,,,,,,,,,,,,,,,,,,,,,,,,,,,,,,,,,,,,,,,,,,,,,,,,,,,,,,,,,,,,,,,,,,,,,,,,,,,,,,,,,,,,,,,,,,,,,,,,,,,,,,,,,,,,,,"&",,,,,,,,,,,,,,,,,,,,,,,,,,,,,,,,,,,,,,,,,,,,,,,,,,,,,,,,,,,,,,,,,,,,,,,,,,,,,,,,,,,,,,,,,,,,,,,,,,") -> ,,,,,,,,,,,,,,,,,,,,,,,,,,,,,,,,,,,,,,,,,,,,,,,,,,,,,,,,,,,,,,,,,,,,,,,,,,,,,,,,,,,,,,,,,,,,,,,,,,,,,,,,,,,,,,,,,,,,,,,,,,,,,,,,,,,,,,,,,,,,,,,,,,,,,,,,,,,,,,,,,,,,,,,,,,,,,,,,,,,,,,,,,,,,,,,,,,,,,,,,,,,,,,,,,,,,,,,,,,,,,,,,,,,,,,,,,,,,,,,,,,,,,,,,,,,,,,,,,,,,,,,,,,,,,,,,,,,,,,,,,,,,,,,,,,,,,,,,,,,,,,,,,,,,,,,,,,,,,,,,,,,,,,,,,,,,,,,,,,,,,,,,,,,,,,,,,,,,,,,,,,,,,,,,,,,,,,,,,,,,,,,,,,,,,,,,,,,,,,,,,,,,,,,,,,,,,,,,,,,,,,,,,,,,,,,,,,,,,,,,,,,,,,,,,,,,,,,,,,,,,,,,,,,,,,,,,,,,,,,,,,,,,,,,,,,,,,,,,,,,,,,,,,,,,,,,,,,,,,,,,,,,,,,,,,,,,,,,,,,,,,,,,,,,,,,,,,,,,,,,,,,,,,,,,,,,,,,,,,,,,,,,,,,,,,,,,,,,,,,,,,,,,,,,,,,,,,,,,,,,,,,,,,,,,,,,,,,,,,,,,,,,,,,,,,,,,,,,,,,,,,,,,,,,,,,,,,,,,,,,,,,,,,,,,,,,,,,,,,,,,,,,,,,,,,,,,,,,,,,,,,,,,,,,,,,,,,,,,,,,,,,,,,,,,,,,,,,,,,,,,,,,,,,,,,,,,,,,,,,,,,,,,,,,,,,,,,,,,,,,,,,,,,,,,,,,,,,,,,,,,,,,,,,,,,,,,,,,,,,,,,,,,,,,,,,,,,,,,,,,,,,,,,,,,,,,,,,,,,,,,,,,,,,,,,,,,,,,,,,,,,,,,,,,,,,,,,,,,,,,,,,,,,,,,,,,,,,,,,,,,,,,,,,,,,,,,,,,,,,,,,,,,,,,,,,,,,,,,,,,,,,,,,,,,,,,,,,,,,,,,,,,,,,,,,,,,,,,,,,,,,,,,,,,,,,,,,,,,,,,,,,,,,,,,,,,,,,,,,,,,,,,,,,,,,,,,,,,,,,,,,,,,,,,,,,,,,,,,,,,,,,,,,,,,,,,,,,,,,,,,,,,,,,,,,,,,,,,,,,,,,,,,,,,,,,,,,,,,,,,,,,,,,,,,,,,,,,,,,,,,,,,,,,,,,,,,,,,,,,,,,,,,,,,,,,,,,,,,,,,,,,,,,,,,,,,,,,,,,,,,,,,,,,,,,,,,,,,,,,,,,,,,,,,,,,,,,,,,,,,,,,,,,,,,,,,,,,,,,,,,,,,,,,,,,,,,,,,,,,,,,,,,,,,,,,,,,,,,,,,,,,,,,,,,,,,,,,,,,,,,,,,,,,,,,,,,,,,,,,,,,,,,,,,,,,,,,,,,,,,,,,,,,,,,,,,,,,,,,,,,,,,,,,,,,,,,,,,,,,,,,,,,,,,,,,,,,,,,,,,,,,,,,,,,,,,,,,,,,,,,,,,,,,,,,,,,,,,,,,,,,,,,,,,,,,,,,,,,,,,,,,,,,,,,,,,,,,,,,,,,,,,,,,,,,,,,,,,,,,,,,,,,,,,,,,,,,,,,,,,,,,,,,,,,,,,,,,,,,,,,,,,,,,,,,,,,,,,,,,,,,,,,,,,,,,,,,,,,,,,,,,,,,,,,,,,,,,,,,,,,,,,,,,,,,,,,,,,,,,,,,,,,,,,,,,,,,,,,,,,,,,,,,,,,,,,,,,,,,,,,,,,,,,,,,,,,,,,,,,,,,,,,,,,,,,,,,,,,,,,,,,,,,,,,,,,,,,,,,,,,,,,,,,,,,,,,,,,,,,,,,,,,,,,,,,,,,,,,,,,,,,,,,,,,,,,,,,,,,,,,,,,,,,,,,,,,,,,,,,,,,,,,,,,,,,,,,,,,,,,,,,,,,,,,,,,,,,,,,,,,,,,,,,,,,,,,,,,,,,,,,,,,,,,,,,,,,,,,,,,,,,,,,,,,,,,,,,,,,,,,,,,,,,,,,,,,,,,,,,,,,,,,,,,,,,,,,,,,,,,,,,,,,,,,,,,,,,,,,,,,,,,,,,,,,,,,,,,,,,,,,,,,,,,,,,,,,,,,,,,,,,,,,,,,,,,,,,,,,,,,,,,,,,,,,,,,,,,,,,,,,,,,,,,,,,,,,,,,,,,,,,,,,,,,,,,,,,,,,,,,,,,,,,,,,,,,,,,,,,,,,,,,,,,,,,,,,,,,,,,,,,,,,,,,,,,,,,,,,,,,,,,,,,,,,,,,,,,,,,,,,,,,,,,,,,,,,,,,,,,,,,,,,,,,,,,,,,,,,,,,,,,,,,,,,,,,,,,,,,,,,,,,,,,,,,,,,,,,,,,,,,,,,,,,,,,,,,,,,,,,,,,,,,,,,,,,,,,,,,,,,,,,,,,,,,,,,,,,,,,,,,,,,,,,,,,,,,,,,,,,,,,,,,,,,,,,,,,,,,,,,,,,,,,,,,,,,,,,,,,,,,,,,,,,,,,,,,,,,,,,,,,,,,,,,,,,,,,,,,,,,,,,,,,,,,,,,,,,,,,,,,,,,,,,,,,,,,,,,,,,,,,,,,,,,,,,,,,,,,,,,,,,,,,,,,,,,,,,,,,,,,,,,,,,,,,,,,,,,,,,,,,,,,,,,,,,,,,,,,,,,,,,,,,,,,,,,,,,,,,,,,,,,,,,,,,,,,,,,,,,,,,,,,,,,,,,,,,,,,,,,,,,,,,,,,,,,,,,,,,,,,,,,,,,,,,,,,,,,,,,,,,,,,,,,,,,,,,,,,,,,,,,,,,,,,,,,,,,,,,,,,,,,,,,,,,,,,,,,,,,,,,,,,,,,,,,,,,,,,,,,,,,,,,,,,,,,,,,,,,,,,,,,,,,,,,,,,,,,,,,,,,,,,,,,,,,,,,,,,,,,,,,,,,,,,,,,,,,,,,,,,,,,,,,,,,,,,,,,,,,,,,,,,,,,,,,,,,,,,,,,,,,,,,,,,,,,,,,,,,,,,,,,,,,,,,,,,,,,,,,,,,,,,,,,,,,,,,,,,,,,,,,,,,,,,,,,,,,,,,,,,,,,,,,,,,,,,,,,,,,,,,,,,,,,,,,,,,,,,,,,,,,,,,,,,,,,,,,,,,,,,,,,,,,,,,,,,,,,,,,,,,,,,,,,,,,,,,,,,,,,,,,,,,,,,,,,,,,,,,,,,,,,,,,,,,,,,,,,,,,,,,,,,,,,,,,,,,,,,,,,,,,,,,,,,,,,,,,,,,,,,,,,,,,,,,,,,,,,,,,,,,,,,,,,,,,,,,,,,,,,,,,,,,,,,,,,,,,,,,,,,,,,,,,,,,,,,,,,,,,,,,,,,,,,,,,,,,,,,,,,,,,,,,,,,,,,,,,,,,,,,,,,,,,,,,,,,,,,,,,,,,,,,,,,,,,,,,,,,,,,,,,,,,,,,,,,,,,,,,,,,,,,,,,,,,,,,,,,,,,,,,,,,,,,,,,,,,,,,,,,,,,,,,,,,,,,,,,,,,,,,,,,,,,,,,,,,,,,,,,,,,,,,,,,,,,,,,,,,,,,,,,,,,,,,,,,,,,,,,,,,,,,,,,,,,,,,,,,,,,,,,,,,,,,,,,,,,,,,,,,,,,,,,,,,,,,,,,,,,,,,,,,,,,,,,,,,,,,,,,,,,,,,,,,,,,,,,,,,,,,,,,,,,,,,,,,,,,,,,,,,,,,,,,,,,,,,,,,,,,,,,,,,,,,,,,,,,,,,,,,,,,,,,,,,,,,,,,,,,,,,,,,,,,,,,,,,,,,,,,,,,,,,,,,,,,,,,,,,,,,,,,,,,,,,,,,,,,,,,,,,,,,,,,,,,,,,,,,,,,,,,,,,,,,,,,,,,,,,,,,,,,,,,,,,,,,,,,,,,,,,,,,,,,,,,,,,,,,,,,,,,,,,,,,,,,,,,,,,,,,,,,,,,,,,,,,,,,,,,,,,,,,,,,,,,,,,,,,,,,,,,,,,,,,,,,,,,,,,,,,,,,,,,,,,,,,,,,,,,,,,,,,,,,,,,,,,,,,,,,,,,,,,,,,,,,,,,,,,,,,,,,,,,,,,,,,,,,,,,,,,,,,,,,,,,,,,,,,,,,,,,,,,,,,,,,,,,,,,,,,,,,,,,,,,,,,,,,,,,,,,,,,,,,,,,,,,,,,,,,,,,,,,,,,,,,,,,,,,,,,,,,,,,,,,,,,,,,,,,,,,,,,,,,,,,,,,,,,,,,,,,,,,,,,,,,,,,,,,,,,,,,,,,,,,,,,,,,,,,,,,,,,,,,,,,,,,,,,,,,,,,,,,,,,,,,,,,,,,,,,,,,,,,,,,,,,,,,,,,,,,,,,,,,,,,,,,,,,,,,,,,,,,,,,,,,,,,,,,,,,,,,,,,,,,,,,,,,,,,,,,,,,,,,,,,,,,,,,,,,,,,,,,,,,,,,,,,,,,,,,,,,,,,,,,,,,,,,,,,,,,,,,,,,,,,,,,,,,,,,,,,,,,,,,,,,,,,,,,,,,,,,,,,,,,,,,,,,,,,,,,,,,,,,,,,,,,,,,,,,,,,,,,,,,,,,,,,,,,,,,,,,,,,,,,,,,,,,,,,,,,,,,,,,,,,,,,,,,,,,,,,,,,,,,,,,,,,,,,,,,,,,,,,,,,,,,,,,,,,,,,,,,,,,,,,,,,,,,,,,,,,,,,,,,,,,,,,,,,,,,,,,,,,,,,,,,,,,,,,,,,,,,,,,,,,,,,,,,,,,,,,,,,,,,,,,,,,,,,,,,,,,,,,,,,,,,,,,,,,,,,,,,,,,,,,,,,,,,,,,,,,,,,,,,,,,,,,,,,,,,,,,,,,,,,,,,,,,,,,,,,,,,,,,,,,,,,,,,,,,,,,,,,,,,,,,,,,,,,,,,,,,,,,,,,,,,,,,,,,,,,,,,,,,,,,,,,,,,,,,,,,,,,,,,,,,,,,,,,,,,,,,,,,,,,,,,,,,,,,,,,,,,,,,,,,,,,,,,,,,,,,,,,,,,,,,,,,,,,,,,,,,,,,,,,,,,,,,,,,,,,,,,,,,,,,,,,,,,,,,,,,,,,,,,,,,,,,,,,,,,,,,,,,,,,,,,,,,,,,,,,,,,,,,,,,,,,,,,,,,,,,,,,,,,,,,,,,,,,,,,,,,,,,,,,,,,,,,,,,,,,,,,,,,,,,,,,,,,,,,,,,,,,,,,,,,,,,,,,,,,,,,,,,,,,,,,,,,,,,,,,,,,,,,,,,,,,,,,,,,,,,,,,,,,,,,,,,,,,,,,,,,,,,,,,,,,,,,,,,,,,,,,,,,,,,,,,,,,,,,,,,,,,,,,,,,,,,,,,,,,,,,,,,,,,,,,,,,,,,,,,,,,,,,,,,,,,,,,,,,,,,,,,,,,,,,,,,,,,,,,,,,,,,,,,,,,,,,,,,,,,,,,,,,,,,,,,,,,,,,,,,,,,,,,,,,,,,,,,,,,,,,,,,,,,,,,,,,,,,,,,,,,,,,,,,,,,,,,,,,,,,,,,,,,,,,,,,,,,,,,,,,,,,,,,,,,,,,,,,,,,,,,,,,,,,,,,,,,,,,,,,,,,,,,,,,,,,,,,,,,,,,,,,,,,,,,,,,,,,,,,,,,,,,,,,,,,,,,,,,,,,,,,,,,,,,,,,,,,,,,,,,,,,,,,,,,,,,,,,,,,,,,,,,,,,,,,,,,,,,,,,,,,,,,,,,,,,,,,,,,,,,,,,,,,,,,,,,,,,,,,,,,,,,,,,,,,,,,,,,,,,,,,,,,,,,,,,,,,,,,,,,,,,,,,,,,,,,,,,,,,,,,,,,,,,,,,,,,,,,,,,,,,,,,,,,,,,,,,,,,,,,,,,,,,,,,,,,,,,,,,,,,,,,,,,,,,,,,,,,,,,,,,,,,,,,,,,,,,,,,,,,,,,,,,,,,,,,,,,,,,,,,,,,,,,,,,,,,,,,,,,,,,,,,,,,,,,,,,,,,,,,,,,,,,,,,,,,,,,,,,,,,,,,,,,,,,,,,,,,,,,,,,,,,,,,,,,,,,,,,,,,,,,,,,,,,,,,,,,,,,,,,,,,,,,,,,,,,,,,,,,,,,,,,,,,,,,,,,,,,,,,,,,,,,,,,,,,,,,,,,,,,,,,,,,,,,,,,,,,,,,,,,,,,,,,,,,,,,,,,,,,,,,,,,,,,,,,,,,,,,,,,,,,,,,,,,,,,,,,,,,,,,,,,,,,,,,,,,,,,,,,,,,,,,,,,,,,,,,,,, | M3: Group | P3: =IFERROR(__xludf.DUMMYFUNCTION("if($D$3=4,filter($M$14:$M$23,$N$14:$N$23=#REF!))"),FALSE) -> FALSE | R3: =IFERROR(__xludf.DUMMYFUNCTION("ifna(join("","",unique(filter(PossibleLayouts!$D$2:$D$30,PossibleLayouts!$C$2:$C$30=$P$3,PossibleLayouts!$B$2:$B$30=$D$3))),"""")"),"") | W3: =IFERROR(__xludf.DUMMYFUNCTION("iferror(transpose(unique(split(textjoin("","",True,P$7:P1000,Q$7:Q1000,R$7:R1000,S$7:S1000,T$7:T1000,U$7:U1000),"",""),1)),""None"")"),"None") -> None | Y3: Group | AD3: =if(and(G3=4,not(AD5=1)),D2,G3) -> #N/A | AE3: =IFERROR(__xludf.DUMMYFUNCTION("filter(PossibleLayouts!$E$2:$E$30,PossibleLayouts!$B$2:$B$30=$AD$3,PossibleLayouts!$C$2:$C$30=$AD$4,PossibleLayouts!$D$2:$D$30=$AD$5)"),"#N/A") -> #N/A | AG3: =textjoin(" ",1,$AE$3:$AE$31) -> #N/A
A4: {=SEQUENCE(10,1)} -> 1 | B4: {=ifna(index(SkillGroups!$B$2:$B$38,match(#REF!,SkillGroups!$A$2:$A$38,0)),0)} -> #REF! | M4: {=SEQUENCE(10,1)} -> 1 | N4: {=ifna(if(not(countif(D$6:I$6,M4)=0),index(SkillGroups!$B$2:$B$38,match(#REF!,SkillGroups!$A$2:$A$38,0)),0),0)} -> 0 | Y4: {=SEQUENCE(10,1)} -> 1 | Z4: {=ifna(if(not(countif(P$6:U$6,Y4)=0),index(SkillGroups!$B$2:$B$38,match(#REF!,SkillGroups!$A$2:$A$38,0)),0),0)} -> 0 | AD4: =P2 -> #N/A | AG4: =IFERROR(__xludf.DUMMYFUNCTION("transpose(split(AG3,"" ""))"),"#N/A") -> #N/A | AH4: {=ifna(index(PossibleLayouts!$H$2:$H$9,match($AG4,PossibleLayouts!$G$2:$G$9,0)),"")}
A5: 2 | B5: {=ifna(index(SkillGroups!$E$2:$E$44,match(#REF!,SkillGroups!$D$2:$D$44,0)),0)} -> #REF! | D5: =IFERROR(__xludf.DUMMYFUNCTION("join("","",unique(split(join("","",F$2,F$3),"",""),1))"),",") -> , | M5: 2 | N5: {=ifna(if(not(countif(D$6:I$6,M5)=0),index(SkillGroups!$E$2:$E$44,match(#REF!,SkillGroups!$D$2:$D$44,0)),0),0)} -> 0 | P5: =IFERROR(__xludf.DUMMYFUNCTION("join("","",unique(split(join("","",R$2,R$3),"",""),1))"),",") -> , | Y5: 2 | Z5: {=ifna(if(not(countif(P$6:U$6,Y5)=0),index(SkillGroups!$E$2:$E$44,match(#REF!,SkillGroups!$D$2:$D$44,0)),0),0)} -> 0 | AD5: =AB2 -> - | AH5: {=ifna(index(PossibleLayouts!$H$2:$H$9,match($AG5,PossibleLayouts!$G$2:$G$9,0)),"")}
A6: 3 | B6: {=ifna(index(SkillGroups!$H$2:$H$41,match(#REF!,SkillGroups!$G$2:$G$41,0)),0)} -> #REF! | D6: =IFERROR(__xludf.DUMMYFUNCTION("split(D$5,"","")"),",") -> , | M6: 3 | N6: {=ifna(if(not(countif(D$6:I$6,M6)=0),index(SkillGroups!$H$2:$H$41,match(#REF!,SkillGroups!$G$2:$G$41,0)),0),0)} -> 0 | P6: =IFERROR(__xludf.DUMMYFUNCTION("split(P$5,"","")"),",") -> , | Y6: 3 | Z6: {=ifna(if(not(countif(P$6:U$6,Y6)=0),index(SkillGroups!$H$2:$H$41,match(#REF!,SkillGroups!$G$2:$G$41,0)),0),0)} -> 0 | AH6: {=ifna(index(PossibleLayouts!$H$2:$H$9,match($AG6,PossibleLayouts!$G$2:$G$9,0)),"")}
A7: 4 | B7: {=ifna(index(SkillGroups!$K$2:$K$22,match(#REF!,SkillGroups!$J$2:$J$22,0)),0)} -> #REF! | D7: =IFERROR(__xludf.DUMMYFUNCTION("ifna(filter(SkillList!$A$2:$A$289,SkillList!$C$2:$C$289=D$6),"""")"),"") | E7: =IFERROR(__xludf.DUMMYFUNCTION("ifna(filter(SkillList!$A$2:$A$289,SkillList!$C$2:$C$289=E$6),"""")"),"") | F7: =IFERROR(__xludf.DUMMYFUNCTION("ifna(filter(SkillList!$A$2:$A$289,SkillList!$C$2:$C$289=F$6),"""")"),"") | G7: =IFERROR(__xludf.DUMMYFUNCTION("ifna(filter(SkillList!$A$2:$A$289,SkillList!$C$2:$C$289=G$6),"""")"),"") | H7: =IFERROR(__xludf.DUMMYFUNCTION("ifna(filter(SkillList!$A$2:$A$289,SkillList!$C$2:$C$289=H$6),"""")"),"") | I7: =IFERROR(__xludf.DUMMYFUNCTION("ifna(filter(SkillList!$A$2:$A$289,SkillList!$C$2:$C$289=I$6),"""")"),"") | M7: 4 | N7: {=ifna(if(not(countif(D$6:I$6,M7)=0),index(SkillGroups!$K$2:$K$22,match(#REF!,SkillGroups!$J$2:$J$22,0)),0),0)} -> 0 | P7: =IFERROR(__xludf.DUMMYFUNCTION("ifna(filter(SkillList!$A$2:$A$289,SkillList!$C$2:$C$289=P$6),"""")"),"") | Q7: =IFERROR(__xludf.DUMMYFUNCTION("ifna(filter(SkillList!$A$2:$A$289,SkillList!$C$2:$C$289=Q$6),"""")"),"") | R7: =IFERROR(__xludf.DUMMYFUNCTION("ifna(filter(SkillList!$A$2:$A$289,SkillList!$C$2:$C$289=R$6),"""")"),"") | S7: =IFERROR(__xludf.DUMMYFUNCTION("ifna(filter(SkillList!$A$2:$A$289,SkillList!$C$2:$C$289=S$6),"""")"),"") | T7: =IFERROR(__xludf.DUMMYFUNCTION("ifna(filter(SkillList!$A$2:$A$289,SkillList!$C$2:$C$289=T$6),"""")"),"") | U7: =IFERROR(__xludf.DUMMYFUNCTION("ifna(filter(SkillList!$A$2:$A$289,SkillList!$C$2:$C$289=U$6),"""")"),"") | Y7: 4 | Z7: {=ifna(if(not(countif(P$6:U$6,Y7)=0),index(SkillGroups!$K$2:$K$22,match(#REF!,SkillGroups!$J$2:$J$22,0)),0),0)} -> 0 | AH7: {=ifna(index(PossibleLayouts!$H$2:$H$9,match($AG7,PossibleLayouts!$G$2:$G$9,0)),"")}
A8: 5 | M8: 5 | N8: {=ifna(if(not(countif(D$6:I$6,M8)=0),index(SkillGroups!$N$2:$N$38,match(#REF!,SkillGroups!$M$2:$M$38,0)),0),0)} -> 0 | Y8: 5 | Z8: {=ifna(if(not(countif(P$6:U$6,Y8)=0),index(SkillGroups!$N$2:$N$38,match(#REF!,SkillGroups!$M$2:$M$38,0)),0),0)} -> 0 | AH8: {=ifna(index(PossibleLayouts!$H$2:$H$9,match($AG8,PossibleLayouts!$G$2:$G$9,0)),"")}
A9: 6 | M9: 6 | N9: {=ifna(if(not(countif(D$6:I$6,M9)=0),index(SkillGroups!$Q$2:$Q$38,match(#REF!,SkillGroups!$P$2:$P$38,0)),0),0)} -> 0 | Y9: 6 | Z9: {=ifna(if(not(countif(P$6:U$6,Y9)=0),index(SkillGroups!$Q$2:$Q$38,match(#REF!,SkillGroups!$P$2:$P$38,0)),0),0)} -> 0 | AH9: {=ifna(index(PossibleLayouts!$H$2:$H$9,match($AG9,PossibleLayouts!$G$2:$G$9,0)),"")}
A10: 7 | M10: 7 | N10: {=ifna(if(not(countif(D$6:I$6,M10)=0),index(SkillGroups!$T$2:$T$35,match(#REF!,SkillGroups!$S$2:$S$35,0)),0),0)} -> 0 | Y10: 7 | Z10: {=ifna(if(not(countif(P$6:U$6,Y10)=0),index(SkillGroups!$T$2:$T$35,match(#REF!,SkillGroups!$S$2:$S$35,0)),0),0)} -> 0 | AH10: {=ifna(index(PossibleLayouts!$H$2:$H$9,match($AG10,PossibleLayouts!$G$2:$G$9,0)),"")}
A11: 8 | M11: 8 | N11: {=ifna(if(not(countif(D$6:I$6,M11)=0),index(SkillGroups!$W$2:$W$16,match(#REF!,SkillGroups!$V$2:$V$16,0)),0),0)} -> 0 | Y11: 8 | Z11: {=ifna(if(not(countif(P$6:U$6,Y11)=0),index(SkillGroups!$W$2:$W$16,match(#REF!,SkillGroups!$V$2:$V$16,0)),0),0)} -> 0 | AH11: {=ifna(index(PossibleLayouts!$H$2:$H$9,match($AG11,PossibleLayouts!$G$2:$G$9,0)),"")}
A12: 9 | M12: 9 | N12: {=ifna(if(not(countif(D$6:I$6,M12)=0),index(SkillGroups!$Z$2:$Z$16,match(#REF!,SkillGroups!$Y$2:$Y$16,0)),0),0)} -> 0 | Y12: 9 | Z12: {=ifna(if(not(countif(P$6:U$6,Y12)=0),index(SkillGroups!$Z$2:$Z$16,match(#REF!,SkillGroups!$Y$2:$Y$16,0)),0),0)} -> 0
A13: 10 | M13: 10 | N13: {=ifna(if(not(countif(D$6:I$6,M13)=0),index(SkillGroups!$AC$2:$AC$10,match(#REF!,SkillGroups!$AB$2:$AB$10,0)),0),0)} -> 0 | Y13: 10 | Z13: {=ifna(if(not(countif(P$6:U$6,Y13)=0),index(SkillGroups!$AC$2:$AC$10,match(#REF!,SkillGroups!$AB$2:$AB$10,0)),0),0)} -> 0
M14: {=SEQUENCE(10,1)} -> 1 | N14: =if(countif($D$6:$I$6,M14)=1,N4,0) -> 0 | Y14: {=SEQUENCE(10,1)} -> 1 | Z14: =if(countif($P$6:$U$6,Y14)=1,Z4,0) -> 0
A15: Possible Level | B15: =IFERROR(__xludf.DUMMYFUNCTION("unique(filter($B$4:$B$13,not($B$4:$B$13=0)))"),"#N/A") -> #N/A | M15: 2 | Y15: 2
M16: 3 | Y16: 3
M17: 4 | Y17: 4
M18: 5 | Y18: 5 | Z18: =if(countif($P$6:$U$6,Y18)=1,Z8,0) -> 0
M19: 6 | N19: =if(countif($D$6:$I$6,M19)=1,N9,0) -> 0 | Y19: 6 | Z19: =if(countif($P$6:$U$6,Y19)=1,Z9,0) -> 0
M20: 7 | N20: =if(countif($D$6:$I$6,M20)=1,N10,0) -> 0 | Y20: 7 | Z20: =if(countif($P$6:$U$6,Y20)=1,Z10,0) -> 0
M21: 8 | N21: =if(countif($D$6:$I$6,M21)=1,N11,0) -> 0 | Y21: 8 | Z21: =if(countif($P$6:$U$6,Y21)=1,Z11,0) -> 0
M22: 9 | N22: =if(countif($D$6:$I$6,M22)=1,N12,0) -> 0 | Y22: 9
M23: 10 | N23: =if(countif($D$6:$I$6,M23)=1,N13,0) -> 0 | Y23: 10 | Z23: =if(countif($P$6:$U$6,Y23)=1,Z13,0) -> 0
M25: Possible Level | N25: =IFERROR(__xludf.DUMMYFUNCTION("unique(filter(N$14:N$23,not(N$14:N$23=0)))"),"#N/A") -> #N/A | Y25: Possible Level | Z25: =IFERROR(__xludf.DUMMYFUNCTION("ifna(unique(filter(Z$14:Z$23,not(Z$14:Z$23=0))),0)"),0.0) -> 0

Sheet SkillList
A1: Skill | B1: Level | C1: Group
A2: Artillery | B2: 1 | C2: 1
A3: Attack Boost | B3: 1 | C3: 1
A4: Ballistics | B4: 1 | C4: 1
A5: Blast Attack | B5: 1 | C5: 1
A6: Bludgeoner | B6: 1 | C6: 1
A7: Charge Master | B7: 1 | C7: 1
A8: Critical Draw | B8: 1 | C8: 1
A9: Critical Element | B9: 1 | C9: 1
A10: Critical Eye | B10: 1 | C10: 1
A11: Critical Status | B11: 1 | C11: 1
A12: Dragon Attack | B12: 1 | C12: 1
A13: Fire Attack | B13: 1 | C13: 1
... A289: Weakness Exploit | B289: 1 | C289: 10
